<?xml version="1.0" ?>
<!-- =================================================================================== -->
<!-- |    This document was autogenerated by xacro from sentry_robot_sim.xacro         | -->
<!-- |    EDITING THIS FILE BY HAND IS NOT RECOMMENDED                                 | -->
<!-- =================================================================================== -->
<robot name="sentry_robot">
  <link name="dummy"/>
  <link name="base_link">
    <visual>
      <geometry>
        <box size="0.2 .3 .1"/>
      </geometry>
      <origin rpy="0 0 1.5707963" xyz="0 0 0.05"/>
      <material name="white">
        <color rgba="1 1 1 1"/>
      </material>
    </visual>
    <collision>
      <geometry>
        <box size="0.2 .3 0.1"/>
      </geometry>
      <origin rpy="0 0 1.5707963" xyz="0 0 0.05"/>
    </collision>
    <inertial>
      <mass value="8.2"/>
      <inertia ixx="0.01" ixy="0.0" ixz="0.0" iyy="0.01" iyz="0.0" izz="0.01"/>
    </inertial>
  </link>
  <joint name="dummy_joint" type="fixed">
    <parent link="dummy"/>
    <child link="base_link"/>
  </joint>
  <link name="wheel_1">
    <visual>
      <geometry>
        <cylinder length="0.05" radius="0.06"/>
      </geometry>
      <origin rpy="0 0 0" xyz="0 0 0"/>
      <material name="black">
        <color rgba="0 0 0 1"/>
      </material>
    </visual>
    <collision>
      <geometry>
        <cylinder length="0.05" radius="0.06"/>
      </geometry>
    </collision>
    <mu1>0.5</mu1>
    <mu2>0.5</mu2>
    <inertial>
      <mass value="0.5"/>
      <inertia ixx="0.01" ixy="0.0" ixz="0.0" iyy="0.01" iyz="0.0" izz="0.01"/>
    </inertial>
  </link>
  <link name="wheel_2">
    <visual>
      <geometry>
        <cylinder length="0.05" radius="0.06"/>
      </geometry>
      <origin rpy="0 0 0" xyz="0 0 0"/>
      <material name="black"/>
    </visual>
    <collision>
      <geometry>
        <cylinder length="0.05" radius="0.06"/>
      </geometry>
    </collision>
    <mu1>0.5</mu1>
    <mu2>0.5</mu2>
    <inertial>
      <mass value="0.5"/>
      <inertia ixx="0.01" ixy="0.0" ixz="0.0" iyy="0.01" iyz="0.0" izz="0.01"/>
    </inertial>
  </link>
  <link name="wheel_3">
    <visual>
      <geometry>
        <cylinder length="0.05" radius="0.06"/>
      </geometry>
      <origin rpy="0 0 0" xyz="0 0 0"/>
      <material name="black"/>
    </visual>
    <collision>
      <geometry>
        <cylinder length="0.05" radius="0.06"/>
      </geometry>
    </collision>
    <mu1>0.5</mu1>
    <mu2>0.5</mu2>
    <inertial>
      <mass value="0.5"/>
      <inertia ixx="0.01" ixy="0.0" ixz="0.0" iyy="0.01" iyz="0.0" izz="0.01"/>
    </inertial>
  </link>
  <link name="wheel_4">
    <visual>
      <geometry>
        <cylinder length="0.05" radius="0.06"/>
      </geometry>
      <origin rpy="0 0 0" xyz="0 0 0"/>
      <material name="black"/>
    </visual>
    <collision>
      <geometry>
        <cylinder length="0.05" radius="0.06"/>
      </geometry>
    </collision>
    <mu1>0.5</mu1>
    <mu2>0.5</mu2>
    <inertial>
      <mass value="0.5"/>
      <inertia ixx="0.01" ixy="0.0" ixz="0.0" iyy="0.01" iyz="0.0" izz="0.01"/>
    </inertial>
  </link>
  <joint name="base_to_wheel1" type="continuous">
    <parent link="base_link"/>
    <child link="wheel_1"/>
    <origin rpy="-1.5707963 0 0" xyz="0.1 0.13 0"/>
    <axis xyz="0 0 1"/>
  </joint>
  <joint name="base_to_wheel2" type="continuous">
    <axis xyz="0 0 1"/>
    <anchor xyz="0 0 0"/>
    <limit effort="100" velocity="100"/>
    <parent link="base_link"/>
    <child link="wheel_2"/>
    <origin rpy="-1.5707963 0 0" xyz="-0.1 0.13 0"/>
  </joint>
  <joint name="base_to_wheel3" type="continuous">
    <parent link="base_link"/>
    <axis xyz="0 0 1"/>
    <child link="wheel_3"/>
    <origin rpy="-1.5707963 0 0" xyz="0.1 -0.13 0"/>
  </joint>
  <joint name="base_to_wheel4" type="continuous">
    <parent link="base_link"/>
    <axis xyz="0 0 1"/>
    <child link="wheel_4"/>
    <origin rpy="-1.5707963 0 0" xyz="-0.1 -0.13 0"/>
  </joint>
  <!-- IMU joint -->
  <joint name="imu_joint" type="fixed">
    <axis xyz="0 1 0"/>
    <origin rpy="0 0 0" xyz="0.12 0 0.125"/>
    <parent link="base_link"/>
    <child link="imu_link"/>
  </joint>
  <!-- IMU -->
  <link name="imu_link">
    <collision>
      <origin rpy="0 0 0" xyz="0 0 0"/>
      <geometry>
        <box size="0.05 0.05 0.05"/>
      </geometry>
    </collision>
    <visual>
      <origin rpy="0 0 0" xyz="0 0 0"/>
      <geometry>
        <box size="0.05 0.05 0.05"/>
      </geometry>
      <material name="green">
        <color rgba="0 1 0 1"/>
      </material>
    </visual>
    <inertial>
      <mass value="1e-2"/>
      <origin rpy="0 0 0" xyz="0 0 0"/>
      <inertia ixx="1e-6" ixy="0" ixz="0" iyy="1e-6" iyz="0" izz="1e-6"/>
    </inertial>
  </link>
  <!-- Gazebo插件设置相关 -->
  <gazebo reference="base_link">
    <material>Gazebo/Orange</material>
  </gazebo>
  <gazebo reference="wheel_1">
    <material>Gazebo/Red</material>
  </gazebo>
  <gazebo reference="wheel_2">
    <material>Gazebo/Black</material>
  </gazebo>
  <gazebo reference="wheel_3">
    <material>Gazebo/Red</material>
  </gazebo>
  <gazebo reference="wheel_4">
    <material>Gazebo/Black</material>
  </gazebo>
  <gazebo reference="imu_link">
    <material>Gazebo/BuildingFrame</material>
  </gazebo>
  <gazebo reference="livox_frame">
    <material>Gazebo/LightBlueLaser</material>
  </gazebo>
  <!-- Drive controller plugin-->
  <!-- https://github.com/ros-simulation/gazebo_ros_pkgs/wiki/ROS-2-Migration:-Planar-Move -->
  <gazebo>
    <plugin filename="libgazebo_ros_planar_move.so" name="mecanum_controller">
      <ros>
        <!-- Add a namespace -->
        <namespace>/</namespace>
        <!-- Remap the default topic -->
        <remapping>cmd_vel:=cmd_vel_chassis</remapping>
        <remapping>odom:=odom</remapping>
      </ros>
      <!-- Set control loop update rate -->
      <update_rate>100</update_rate>
      <!-- Set odom publish rate -->
      <publish_rate>10</publish_rate>
      <!-- Set if odom required -->
      <publish_odom>false</publish_odom>
      <publish_odom_tf>false</publish_odom_tf>
      <!-- Frame IDs -->
      <odometry_frame>odom</odometry_frame>
      <robot_base_frame>base_link</robot_base_frame>
      <!-- Set odom covariance -->
      <covariance_x>0.0001</covariance_x>
      <covariance_y>0.0001</covariance_y>
      <covariance_yaw>0.01</covariance_yaw>
    </plugin>
  </gazebo>
  <!-- mid360_imu plugin -->
  <!-- https://github.com/ros-simulation/gazebo_ros_pkgs/wiki/ROS-2-Migration:-IMU-Sensors -->
  <gazebo reference="imu_link">
    <sensor name="mid360_imu" type="imu">
      <always_on>true</always_on>
      <update_rate>100</update_rate>
      <plugin filename="libgazebo_ros_imu_sensor.so" name="imu_plugin">
        <ros>
          <namespace>/</namespace>
          <remapping>~/out:=/livox/imu</remapping>
        </ros>
        <frame_name>imu_link</frame_name>
      </plugin>
    </sensor>
  </gazebo>
  <link name="livox_frame">
    <visual>
      <origin rpy="1.5707963267948966 0 3.141592653589793" xyz="0.025 -0.0265 -0.025"/>
      <geometry>
        <mesh filename="model://mid360.stl" scale="0.0008 0.0008 0.0008"/>
      </geometry>
    </visual>
  </link>
  <joint name="livox_frame_joint" type="fixed">
    <parent link="base_link"/>
    <child link="livox_frame"/>
    <origin rpy="0 0 0" xyz="0.12 0.0 0.175"/>
  </joint>
  <gazebo reference="livox_frame">
    <sensor name="livox_frame" type="ray">
      <pose>0 0 0 0 0 0</pose>
      <visualize>true</visualize>
      <update_rate>10</update_rate>
      <plugin filename="libros2_livox.so" name="livox_frame_plugin">
        <ray>
          <scan>
            <horizontal>
              <samples>100</samples>
              <resolution>1</resolution>
              <min_angle>0</min_angle>
              <max_angle>6.2831852</max_angle>
            </horizontal>
            <vertical>
              <samples>360</samples>
              <resolution>1</resolution>
              <min_angle>-0.12601276984444446</min_angle>
              <max_angle>0.9637707965111111</max_angle>
            </vertical>
          </scan>
          <range>
            <min>0.1</min>
            <max>200.0</max>
            <resolution>0.002</resolution>
          </range>
          <noise>
            <type>gaussian</type>
            <mean>0.0</mean>
            <stddev>0.002</stddev>
          </noise>
        </ray>
        <visualize>false</visualize>
        <samples>30000</samples>
        <downsample>1</downsample>
        <csv_file_name>/home/ros2/Desktop/MY_nav/install/ros2_livox_simulation/share/ros2_livox_simulation/scan_mode/mid360.csv</csv_file_name>
        <topic>/livox/lidar</topic>
      </plugin>
    </sensor>
  </gazebo>
</robot>
